Workbook

Sheet Larsonpkg
A1: Google
A2: Campaign performance
A3: September 1, 2026 - September 30, 2026
A4: Campaign | B4: Campaign state | C4: Campaign type | D4: Clicks | E4: Impr. | F4: CTR | G4: Currency code | H4: Avg. CPC | I4: Cost | J4: Impr. (Abs. Top) % | K4: Impr. (Top) % | L4: Conversions | M4: View-through conv. | N4: Cost / conv. | O4: Conv. rate
A5: LPC - subscribe ads 9/24/25 | B5: Paused | C5: Demand Gen | D5: 293 | E5: 42925 | F5: 0.0068 | G5: USD | H5: 1.32 | I5: 386.12 | J5: n.a. | K5: n.a. | L5: 286 | M5: 0 | N5: 1.35 | O5: 0.1885
A6: LPC - Web traffic - homepage - 6/7/26 | B6: Enabled | C6: Performance Max | D6: 1224 | E6: 33464 | F6: 0.0366 | G6: USD | H6: 2.81 | I6: 3440.57 | J6: n.a. | K6: n.a. | L6: 43 | M6: 0 | N6: 80.02 | O6: 0.0133
A7: Pelican - lead - home page 15/8/25 | B7: Enabled | C7: Search | D7: 805 | E7: 9123 | F7: 0.0882 | G7: USD | H7: 2.09 | I7: 1682.48 | J7: 0.2008 | K7: 0.6876 | L7: 12 | M7: 0 | N7: 140.20667 | O7: 0.0149
A8: Pelican - Web traffic - homepage - 6/29/26 | B8: Enabled | C8: Performance Max | D8: 134 | E8: 6107 | F8: 0.0219 | G8: USD | H8: 2.24 | I8: 300.21 | J8: n.a. | K8: n.a. | L8: 1 | M8: 0 | N8: 300.21 | O8: 0.002
A10: Total | D10: =SUM(D5:D9) -> 2456 | E10: =SUM(E5:E9) -> 91619 | F10: =D10/E10 -> 0.026806667 | G10: USD | H10: =I10/D10 -> 2.3653827 | I10: =SUM(I5:I9) -> 5809.38 | J10: 0.2008 | K10: 0.6876 | L10: =SUM(L5:L9) -> 342 | M10: =SUM(M5:M9) -> 0 | N10: =I10/L10 -> 16.986491 | O10: 0.0565
A12: Key metrics | B12: This month | C12: Previous month | D12: Change
A13: Cost | B13: =I10 -> 5809.38 | C13: 5515.31 | D13: =(B13-C13)/C13 -> 0.053318852
A14: LPC cost | B14: =SUM(I5:I6) -> 3826.69 | C14: 3537.2 | D14: =(B14-C14)/C14 -> 0.08184157
A15: Pelican cost | B15: =SUM(I7:I8) -> 1982.69 | C15: 1978.12 | D15: =(B15-C15)/C15 -> 0.0023102744
A16: Impression | B16: =E10 -> 91619 | C16: 139109 | D16: =(B16-C16)/C16 -> -0.34138697
A17: Click | B17: =D10 -> 2456 | C17: 2388 | D17: =(B17-C17)/C17 -> 0.028475712
A18: CPC | B18: =B13/B17 -> 2.3653827 | C18: 2.31 | D18: =(B18-C18)/C18 -> 0.02397521
A19: CTR | B19: =B17/B16 -> 0.026806667 | C19: 0.0172 | D19: =(B19-C19)/C19 -> 0.55852714
A20: Lead | B20: =SUM(L6:L8) -> 56 | C20: 61.5 | D20: =(B20-C20)/C20 -> -0.089430894
A21: CPL (account level) | B21: =B13/B20 -> 103.73893 | C21: 89.679837 | D21: =(B21-C21)/C21 -> 0.15676981
A22: Youtube subscriber | B22: =L5 -> 286 | C22: 935 | D22: =(B22-C22)/C22 -> -0.69411765
A24: Performance Analysis
A25: In September, we spend $5,800, quite stable compared to last month
A26: Your account reached 91,619 impressions and 2,456 clicks last month. Despite the drop in volume, you generated 342 total conversions at an average cost per conversion of $16.99.
A27: The drop in impression is due to campaign Youtube scriberes pausing
A28: Your CPL increased 15.68%. But overall it still in control at $103
A29: CPC is stable compare to last month
A30: Overral, you have stable results compare to last month
A32: Search term and keywords analysis
A33: Top Keyword Performance
A34: "Custom foam cases" was a primary driver in September, generating 5 conversions at a $352.56 spend with a 5.78% CTR.
A35: The "Pelican cases" keyword saw a CPC reduction from $4.92 to $4.19, though it yielded 2 fewer conversions (5 vs 3) than in August.
A36: Keyword metrics reveal "SKB cases" yielded 1 conversion in August at $71.04 spend, with spend decreasing to $21.86 in September.
... A74: Keep LinkedIn paused and proceed with testing OpenAI ads to diversify high-intent traffic sources.

Sheet Insight report
A16: Chart 1: Session source
A18: Traffic Source Performance
A19: Total GA4 sessions grew to 6,174 (+31%) in September from 4,699 in August.
A20: Google sessions (2,821) achieved 59.06% engagement and 120 key events, while Direct sessions (2,674) resulted in 39 key events.
A21: Mautic emerged as a source with 229 sessions and 0 key events in September.
A22: Bing sessions increased to 177 from 117 in August, while ChatGPT.com sessions decreased slightly to 67 from 73.
A23: LinkedIn traffic (15 sessions via linkedin and linkedin.com) was outside the top five sources for September.
A24: The "Other" category (206 sessions) transparently includes the 15-session residual to align with the 6,174 session total.
A26: Audience Behavior
A43: Who Is Your Audience?
A44: 84% of September clicks have known age/gender data.
A45: Males aged 18–24 and 45–54 are the most active identified segments for non-subscriber leads.
... A82: Region data excludes subscribe campaigns and retains zero-conversion regions. Regional total: $5,319.71 / 54 conversions; unmatched geography is outside this regional table.

Sheet search term and keyword
A1: Search terms report
A2: September 1, 2026 - September 30, 2026 | Cost > $0 | 397 search terms
A3: Search term | B3: Match type | C3: Campaign | D3: Keyword | E3: CTR | F3: Avg. CPC | G3: Cost | H3: Conv. rate | I3: Conversions | J3: Cost / conv.
A4: Total: Account | E4: 0.0268 | F4: 2.37 | G4: 5809.38 | H4: 0.0565 | I4: 342 | J4: 16.99
A5: Total: Performance Max | E5: 0.0343 | F5: 2.75 | G5: 3740.78 | H5: 0.0118 | I5: 44 | J5: 85.02
A6: Total: Filtered search terms | E6: 0.1273 | F6: 3.1 | G6: 2015.65 | H6: 0.0323 | I6: 21 | J6: 95.98
A7: Total: Search | E7: 0.0882 | F7: 2.09 | G7: 1682.48 | H7: 0.0149 | I7: 12 | J7: 140.21
A8: Total: Demand Gen | E8: 0.0068 | F8: 1.32 | G8: 386.12 | H8: 0.1885 | I8: 286 | J8: 1.35
A9: larson packaging | B9: Performance Max | C9: LPC - Web traffic - homepage - 6/7/26 | D9: — | E9: 0.2778 | F9: 1.17 | G9: 52.87 | H9: 0.0222 | I9: 1 | J9: 52.87
A10: larson packaging company | B10: Performance Max | C10: LPC - Web traffic - homepage - 6/7/26 | D10: — | E10: 0.3015 | F10: 0.88 | G10: 52.84 | H10: 0 | I10: 0 | J10: 0
A11: pelican case | B11: Performance Max | C11: LPC - Web traffic - homepage - 6/7/26 | D11: — | E11: 0.0292 | F11: 5.06 | G11: 50.63 | H11: 0.1 | I11: 1 | J11: 50.63
A12: custom case group | B12: Performance Max | C12: LPC - Web traffic - homepage - 6/7/26 | D12: — | E12: 0.1111 | F12: 46.63 | G12: 46.63 | H12: 1 | I12: 1 | J12: 46.63
A13: merrill's packaging inc | B13: Performance Max | C13: Pelican - Web traffic - homepage - 6/29/26 | D13: — | E13: 0.3333 | F13: 45.09 | G13: 45.09 | H13: 1 | I13: 1 | J13: 45.09
A14: custom foam inserts | B14: Exact match (close variant) | C14: Pelican - lead - home page 15/8/25 | D14: custom foam cases | E14: 0.2308 | F14: 5.26 | G14: 31.54 | H14: 0.1667 | I14: 1 | J14: 31.54
A15: skb cases | B15: Performance Max | C15: LPC - Web traffic - homepage - 6/7/26 | D15: — | E15: 0.0909 | F15: 4.15 | G15: 29.05 | H15: 0.1429 | I15: 1 | J15: 29.05
A16: she pallets | B16: Performance Max | C16: LPC - Web traffic - homepage - 6/7/26 | D16: — | E16: 0.25 | F16: 13.63 | G16: 27.25 | H16: 0 | I16: 0 | J16: 0
A17: custom box packaging | B17: Performance Max | C17: Pelican - Web traffic - homepage - 6/29/26 | D17: — | E17: 0.5 | F17: 26.09 | G17: 26.09 | H17: 0 | I17: 0 | J17: 0
A18: pelican intl inc | B18: Performance Max | C18: LPC - Web traffic - homepage - 6/7/26 | D18: — | E18: 1 | F18: 25.1 | G18: 25.1 | H18: 0 | I18: 0 | J18: 0
A19: pelican | B19: Performance Max | C19: LPC - Web traffic - homepage - 6/7/26 | D19: — | E19: 0.0262 | F19: 5.01 | G19: 25.03 | H19: 0.2 | I19: 1 | J19: 25.03
A20: arizona corrugated container | B20: Performance Max | C20: LPC - Web traffic - homepage - 6/7/26 | D20: — | E20: 0.1 | F20: 24.25 | G20: 24.25 | H20: 0 | I20: 0 | J20: 0
... A405: larson pallets | B405: Performance Max | C405: LPC - Web traffic - homepage - 6/7/26 | D405: — | E405: 0.5 | F405: 0.01 | G405: 0.01 | H405: 0 | I405: 0 | J405: 0

Sheet data
A1: # ----------------------------------------
A2: # Traffic acquisition: Session source
A3: # Account: Larson Pallet & Crating
A4: # Property: Larson Packaging Company
A5: # ----------------------------------------
A6: #
A7: # All Users
A8: # Start date: 20260901
A9: # End date: 20260930
A10: Session source | B10: Sessions | C10: Engaged sessions | D10: Engagement rate | E10: Average engagement time per session | F10: Events per session | G10: Event count | H10: Key events | I10: Session key event rate | J10: Total revenue
A11: google | B11: 2821 | C11: 1666 | D11: 0.59057072 | E11: 39.156682 | F11: 5.3739809 | G11: 15160 | H11: 120 | I11: 0.02516838 | J11: 0
A12: (direct) | B12: 2674 | C12: 1056 | D12: 0.39491399 | E12: 15.420344 | F12: 4.0426328 | G12: 10810 | H12: 39 | I12: 0.0074794316 | J12: 0
A13: Mautic | B13: 229 | C13: 13 | D13: 0.056768559 | E13: 2.2227074 | F13: 3.3187773 | G13: 760 | H13: 0 | I13: 0 | J13: 0
A14: bing | B14: 177 | C14: 106 | D14: 0.59887006 | E14: 58.960452 | F14: 6.0112994 | G14: 1064 | H14: 5 | I14: 0.02259887 | J14: 0
A15: chatgpt.com | B15: 67 | C15: 38 | D15: 0.56716418 | E15: 30.597015 | F15: 5.4179104 | G15: 363 | H15: 6 | I15: 0.059701493 | J15: 0
A16: business.pelican.com | B16: 25 | C16: 20 | D16: 0.8 | E16: 50.44 | F16: 7.32 | G16: 183 | H16: 1 | I16: 0.04 | J16: 0
A17: aocr.org | B17: 23 | C17: 0 | D17: 0 | E17: 0 | F17: 3 | G17: 69 | H17: 0 | I17: 0 | J17: 0
A18: (data not available) | B18: 19 | C18: 12 | D18: 0.63157895 | E18: 29.210526 | F18: 7.5789474 | G18: 144 | H18: 0 | I18: 0 | J18: 0
A19: (not set) | B19: 18 | C19: 0 | D19: 0 | E19: 18.5 | F19: 2.1666667 | G19: 39 | H19: 0 | I19: 0 | J19: 0
A20: teams.public.onecdn.static.microsoft | B20: 14 | C20: 7 | D20: 0.5 | E20: 27 | F20: 3.9285714 | G20: 55 | H20: 0 | I20: 0 | J20: 0
A21: linkedin.com | B21: 13 | C21: 9 | D21: 0.69230769 | E21: 25.076923 | F21: 5.3846154 | G21: 70 | H21: 0 | I21: 0 | J21: 0
A22: customcases.local | B22: 8 | C22: 6 | D22: 0.75 | E22: 299.375 | F22: 10.75 | G22: 86 | H22: 2 | I22: 0.25 | J22: 0
... A57: GA4 displayed report total | B57: 6174 | C57: 2961 | D57: 0.4796 | E57: 28 | F57: 4.72 | G57: 29151 | H57: 177 | I57: 0.017 | J57: 0
A58: Unallocated sessions: displayed total less exported sources | B58: =B57-SUM(B11:B56) -> 15
A60: GA4 export: 46 sources, 6,159 sessions; displayed report total: 6,174. Other includes the 15-session residual.
A62: Audience source: Google Ads Overview, September 1–30, Campaign name does not contain subscribe. 35 campaigns; only 3 had spend.
A63: Devices (Cost / Clicks / Submit lead forms): Mobile 59.2% / 68.4% / 25.8%; Computers 40.5% / 30.5% / 74.2%.
A64: Demographics: 84% known age/gender; male 18–24 darkest click heatmap cell. Timing: Tuesday strongest; morning peak around 9–10 AM, Pacific Time.
A65: Non-subscriber displayed view cost: $5,423.27; rounded campaign-row cost sum: $5,423.26.
A66: Lead definition: standard Conversions for non-subscriber campaigns. Subscriber campaign Conversions are subscriber counts.
A67: Analysis source: Google Ads Advisor, queried October 7, 2026 for September 1–30 versus August 1–31.
A68: Google Ads campaign report: Cost > $0; four campaigns; View-through conversions = 0; Search absolute-top/top impression rates 20.08% / 68.76%.
A70: Matched locations report — Region — September 1–30, 2026 — subscriber campaigns excluded
A71: September 1, 2026 - September 30, 2026
A72: Matched location | B72: Currency code | C72: Cost | D72: Conversions | E72: Cost / conv. | F72: Conv. rate | G72: CTR | H72: Avg. CPC
A73: California, United States | B73: USD | C73: 1591.92 | D73: 15 | E73: 106.13 | F73: 0.0154 | G73: 0.0505 | H73: 2.59
A74: San Francisco Bay Area, California, United States | B74: USD | C74: 784.27 | D74: 4 | E74: 196.07 | F74: 0.0053 | G74: 0.0717 | H74: 1.48
A75: Texas, United States | B75: USD | C75: 242.89 | D75: 2 | E75: 121.44 | F75: 0.0063 | G75: 0.0297 | H75: 3.04
A76: Silicon Valley, California, United States | B76: USD | C76: 181.77 | D76: 2 | E76: 90.89 | F76: 0.0154 | G76: 0.0457 | H76: 2.84
A77: Florida, United States | B77: USD | C77: 178.33 | D77: 1 | E77: 178.33 | F77: 0.0041 | G77: 0.0435 | H77: 2.12
...

Sheet matched location pivot table
A1: Location | B1: Cost | C1: Cost / conv.
A2: California | B2: =data!C73 -> 1591.92 | C2: =data!E73 -> 106.13
A3: Bay | B3: =data!C74 -> 784.27 | C3: =data!E74 -> 196.07
A4: Texas | B4: =data!C75 -> 242.89 | C4: =data!E75 -> 121.44
A5: Other | B5: =data!C126-SUM(B2:B4) -> 2700.63 | C5: =B5/(data!D126-SUM(data!D73,data!D74,data!D75)) -> 81.837273

Sheet Session source pivot table
B1: Session source | C1: Sessions
B2: google | C2: =data!B11 -> 2821
B3: (direct) | C3: =data!B12 -> 2674
B4: Mautic | C4: =data!B13 -> 229
B5: bing | C5: =data!B14 -> 177
B6: chatgpt.com | C6: =data!B15 -> 67
B7: Other | C7: =SUM(data!B16:B56)+data!B58 -> 206
